Workbook

Sheet Sheet1
A1: Estado de defecto | B1: (Multiple Items)
A2: Frente | B2: (Multiple Items)
A4: Defecto | B4: Responsable del defecto | C4: Antigüedad del defecto (promedio en días)
A5: H0_AA_Error carga con datos que existen (8000001533) | B5: Oscar Mauricio Parada (49) | C5: 9,81
B6: Oscar Mauricio Parada (49) Total
A7: H0_AA_Error carga con datos que existen (8000001533) Total
A8: H0_AA_Genera_error_con_datos_opcionales (8000001535) | B8: Oscar Mauricio Parada (49) | C8: 9,80
B9: Oscar Mauricio Parada (49) Total
A10: H0_AA_Genera_error_con_datos_opcionales (8000001535) Total
A11: H0_AA_Límite_procesamiento_10mil_registr (8000001529) | B11: Oscar Mauricio Parada (49) | C11: 9,81
B12: Oscar Mauricio Parada (49) Total
A13: H0_AA_Límite_procesamiento_10mil_registr (8000001529) Total
A14: H0_FM_1231_Ejec Gast GT (8000001260) | B14: Lina María Rodríguez Bailón (171) | C14: 20,94
B15: Lina María Rodríguez Bailón (171) Total
A16: H0_FM_1231_Ejec Gast GT (8000001260) Total
A17: H0_TX_1208_F1001 Valores duplicados (8000001228) | B17: Ana Maria Brito Llerena (151) | C17: 23,82
B18: Ana Maria Brito Llerena (151) Total
A19: H0_TX_1208_F1001 Valores duplicados (8000001228) Total
A20: H0_TX_1211_F1005 Sin columna de iva (8000001212) | B20: Ana Maria Brito Llerena (151) | C20: 23,85
B21: Ana Maria Brito Llerena (151) Total
A22: H0_TX_1211_F1005 Sin columna de iva (8000001212) Total
A23: H0_TX_1235_F1001 Errores XML (8000001237) | B23: Ana Maria Brito Llerena (151) | C23: 23,81
B24: Ana Maria Brito Llerena (151) Total
A25: H0_TX_1235_F1001 Errores XML (8000001237) Total
A26: H0_TX_1248_Errorcargamanualformato1001 (8000001272) | B26: Ana Maria Brito Llerena (151) | C26: 20,83
B27: Ana Maria Brito Llerena (151) Total
A28: H0_TX_1248_Errorcargamanualformato1001 (8000001272) Total
A29: H1_FM_758 Controller (8000001296) | B29: Jenny Carolina Suarez (101) | C29: 20,69
B30: Jenny Carolina Suarez (101) Total
A31: H1_FM_758 Controller (8000001296) Total
A32: H1_TR/BCM_FORMATO ARCHIVO TXT BANCO ITAU (8000001527) | B32: Manuel Escalante (131) | C32: 9,89
B33: Manuel Escalante (131) Total
A34: H1_TR/BCM_FORMATO ARCHIVO TXT BANCO ITAU (8000001527) Total
A35: H1_TX_1234_F1001 Valor retenciones (8000001235) | B35: Ana Maria Brito Llerena (151) | C35: 23,81
B36: Ana Maria Brito Llerena (151) Total
A37: H1_TX_1234_F1001 Valor retenciones (8000001235) Total
A38: H1_TX_1272_No despliega información (8000001239) | B38: Ana Maria Brito Llerena (151) | C38: 23,80
B39: Ana Maria Brito Llerena (151) Total
A40: H1_TX_1272_No despliega información (8000001239) Total
A41: H3_AA_668_ Liberación de reserva fiscal (8000001281) | B41: Oscar Mauricio Parada (49) | C41: 20,82
...

Sheet informacion_extra
A1: Defecto | B1: Responsable del defecto | C1: Autor del defecto | D1: Antigüedad del defecto (promedio en días) | E1: Categoría de defecto | F1: Estado de defecto
A2: H0_ RE_ CONTABILIDA FINANCIERA AGN (8000001462) | B2: NATALIA EUGENIA RAMIREZ MOLINA (193) | C2: NATALIA EUGENIA RAMIREZ MOLINA (193) | D2: 14,62 | E2: Roles y perfiles | F2: Acción responsable test
A3: H0_AA_Error carga con datos que existen (8000001533) | B3: Oscar Mauricio Parada (49) | C3: SEBASTIAN GALLEGO VILLEGAS (147) | D3: 10,61 | E3: Desarrollo | F3: Nuevo
A4: H0_AA_Genera_error_con_datos_opcionales (8000001535) | B4: Oscar Mauricio Parada (49) | C4: SEBASTIAN GALLEGO VILLEGAS (147) | D4: 10,60 | E4: Desarrollo | F4: Nuevo
A5: H0_AA_Lentitud carga de datos en MC (8000001452) | B5: Natalia Manzaneda Palacios (258) | C5: ANA MILENA IBARBO GUTIERREZ (320) | D5: 14,73 | F5: En tratamiento
A6: H0_AA_Límite_procesamiento_10mil_registr (8000001529) | B6: Oscar Mauricio Parada (49) | C6: SEBASTIAN GALLEGO VILLEGAS (147) | D6: 10,61 | E6: Desarrollo | F6: Nuevo
A7: H0_AP_1236_ERROR ANULAR FRA MIRO (8000001412) | B7: Wilmar Vargas Preciado (174) | C7: SINDY CRISTINA ALZATE ARIAS (201) | D7: 18,98 | E7: Configuración | F7: En tratamiento
A8: H0_AP_Error en cargue de FI (8000001501) | B8: Alberto Rivera Betancourt (822) | C8: SINDY CRISTINA ALZATE ARIAS (201) | D8: 11,73 | E8: Desarrollo | F8: En tratamiento
A9: H0_AP_Error en documento soporte (8000001605) | B9: Alberto Rivera Betancourt (822) | C9: SINDY CRISTINA ALZATE ARIAS (201) | D9: 4,65 | E9: Desarrollo | F9: Nuevo
A10: H0_AR_ErrorcargaCXC_ (8000001624) | B10: Juan Manuel Ossa Botero (40) | C10: ADRIANA CAROLINA PEREZ ORTIZ (327) | D10: 1,93 | E10: Configuración | F10: Nuevo
A11: H0_EPM_TR_BOFA CREACION PLATILLA (8000001559) | B11: Manuel Escalante (131) | C11: MANUEL HERNANDO SANTA JARA (132) | D11: 6,88 | F11: Nuevo
A12: H0_EPM_TR_ErrorPagosDavivienda (8000001408) | B12: MANUEL HERNANDO SANTA JARA (132) | C12: MANUEL HERNANDO SANTA JARA (132) | D12: 19,60 | E12: Desarrollo | F12: Propuesta de solución
A13: H0_EWM_EWM_SC048_ERROR HU AUTOMATICA (8000001406) | B13: GUSTAVO ADOLFO GARCIA TRUJILLO (393) | C13: GUSTAVO ADOLFO GARCIA TRUJILLO (393) | D13: 19,61 | E13: Funcionales | F13: Acción responsable test
A14: H0_FI_1308_Mensaje error no corresponde (8000001356) | B14: ANA MILENA CHADID JARAMILLO (697) | C14: ANA MILENA CHADID JARAMILLO (697) | D14: 20,64 | E14: Legados | F14: Acción responsable test
A15: H0_FM_1231_Ejec Gast GT (8000001260) | B15: Lina María Rodríguez Bailón (171) | C15: MISAEL ENRIQUE ARAUJO DIAZ (701) | D15: 21,74 | E15: Desarrollo | F15: En tratamiento
A16: H0_FM_1303_Error en cumplimiento tarea (8000001361) | B16: ANA MILENA CHADID JARAMILLO (697) | C16: ANA MILENA CHADID JARAMILLO (697) | D16: 20,62 | F16: Propuesta de solución
A17: H0_FM_R-FI-010 _Diferencia saldo bancos (8000001556) | B17: Lina María Rodríguez Bailón (171) | C17: MISAEL ENRIQUE ARAUJO DIAZ (701) | D17: 6,89 | E17: Desarrollo | F17: En tratamiento
A18: H0_GL_Reclasif Pago Anticipado (8000001512) | B18: John Alejandro Rodriguez (41) | C18: GLORIA ELENA AGUDELO ARENAS (181) | D18: 10,97 | E18: Control de cambio | F18: Nuevo
A19: H0_GR_Conversión Mone Comprobantes (8000001632) | B19: Nicolas Sarmiento (218) | C19: DAMARIS BIVIANA MURCIA SABOYA (103) | D19: 0,94 | E19: Configuración | F19: Nuevo
A20: H0_MM_1141_ROLES Y PERFILES (8000001349) | B20: GUSTAVO ESPINOSA (646) | C20: PAOLA ANDREA JIMENEZ RODRIGUEZ (492) | D20: 20,75 | F20: En tratamiento
A21: H0_MM_1258_Carga registros info Proveed (8000001382) | B21: GUSTAVO ESPINOSA (646) | C21: LUIS GERMAN PINEDA ARCILA (191) | D21: 19,85 | E21: Maestros | F21: En tratamiento
A22: H0_MM_SC120 EROR VISTA WORZONE (8000001414) | B22: PAOLA ANDREA JIMENEZ RODRIGUEZ (492) | C22: PAOLA ANDREA JIMENEZ RODRIGUEZ (492) | D22: 18,96 | F22: Propuesta de solución
A23: H0_PAPM_1294_Capturadecontroladores (8000001391) | B23: Raphael Gustavo Gimenes Trivaleti (219) | C23: JUAN DAVID VARGAS RESTREPO (127) | D23: 19,73 | F23: Nuevo
A24: H0_TR_BCM_ErrorPatronesCarga (8000001378) | B24: CAROLINA ECHEVERRI SANTA (783) | C24: CAROLINA ECHEVERRI SANTA (783) | D24: 19,86 | E24: Configuración | F24: Propuesta de solución
A25: H0_TR_ERROR MONEDA E IMPORTE ME (8000001603) | B25: Nurky Castro (46) | C25: ANGELA PATRICIA PERDOMO (175) | D25: 5,65 | E25: Desarrollo | F25: En tratamiento
A26: H0_TR_ERROR TRASLADO COMPENSACIÓN (8000001582) | B26: Nurky Castro (46) | C26: ANGELA PATRICIA PERDOMO (175) | D26: 6,47 | E26: Desarrollo | F26: En tratamiento
A27: H0_TR/BCM_FORMATO ARCHIVO TXT SUDAMERIS (8000001616) | B27: Manuel Escalante (131) | C27: ANGELA PATRICIA PERDOMO (175) | D27: 2,94 | E27: Configuración | F27: En tratamiento
A28: H0_TR/BCM_PROCESAMIENTO RESP BANCOLOMBIA (8000001618) | B28: Manuel Escalante (131) | C28: ANGELA PATRICIA PERDOMO (175) | D28: 2,47 | E28: Configuración | F28: En tratamiento
A29: H0_TR/BCM_PROCESAMIENTO RESP BBVA (8000001614) | B29: Manuel Escalante (131) | C29: ANGELA PATRICIA PERDOMO (175) | D29: 3,76 | E29: Configuración | F29: En tratamiento
A30: H0_TR/BCM_PROCESAMIENTO RESP BOGOTÁ (8000001622) | B30: Manuel Escalante (131) | C30: ANGELA PATRICIA PERDOMO (175) | D30: 2,42 | E30: Configuración | F30: En tratamiento
A31: H0_TX_1208_F1001 Valores duplicados (8000001228) | B31: Ana Maria Brito Llerena (151) | C31: LINA MARIA SANCHEZ ESCOBAR (771) | D31: 24,62 | E31: Desarrollo | F31: En tratamiento
A32: H0_TX_1211_F1005 Sin columna de iva (8000001212) | B32: Ana Maria Brito Llerena (151) | C32: ELIZABETH MARIA HERNANDEZ RUEDA (767) | D32: 24,65 | E32: Desarrollo | F32: En tratamiento
A33: H0_TX_1235_F1001 Errores XML (8000001237) | B33: Raphael Gustavo Gimenes Trivaleti (219) | C33: LINA MARIA SANCHEZ ESCOBAR (771) | D33: 24,61 | E33: Desarrollo | F33: En tratamiento
A34: H0_TX_1248_Errorcargamanualformato1001 (8000001272) | B34: Raphael Gustavo Gimenes Trivaleti (219) | C34: ELIZABETH MARIA HERNANDEZ RUEDA (767) | D34: 21,63 | E34: Desarrollo | F34: En tratamiento
A35: H0_TX_1301_IVA Incorrecto (8000001241) | B35: Juan Pablo Sanchez Martinez (125) | C35: LINA MARIA SANCHEZ ESCOBAR (771) | D35: 24,60 | E35: Desarrollo | F35: En tratamiento
... A37: H0_TX_Carga Manual (8000001541) | B37: Raphael Gustavo Gimenes Trivaleti (219) | C37: LINA MARIA SANCHEZ ESCOBAR (771) | D37: 8,58 | E37: Desarrollo | F37: En tratamiento
A38: H0_TX_Comparativo por cuentas ICA (8000001596) | B38: Diana Carolina Sanchez Aguirre (165) | C38: LEIDY FABIOLA CARDENAS SUAREZ (188) | D38: 5,87 | F38: En tratamiento
A39: H0_TX_Comparativo por impuestos ICA (8000001594) | B39: Diana Carolina Sanchez Aguirre (165) | C39: LEIDY FABIOLA CARDENAS SUAREZ (188) | D39: 5,87 | F39: En tratamiento
A40: H0_TX_Hoja 2 F-350 Sin información (8000001634) | B40: Elkin Dario Fernandez Camacho (166) | C40: LEIDY FABIOLA CARDENAS SUAREZ (188) | D40: 0,73 | F40: En tratamiento
A41: H0_TX_Renglón 133 F-350 Sin información (8000001636) | B41: LEIDY FABIOLA CARDENAS SUAREZ (188) | C41: LEIDY FABIOLA CARDENAS SUAREZ (188) | D41: 0,72 | F41: Acción responsable test
...

Sheet dinamico
A2: Pendientes IBM
A4: Fecha Propuesta de solución | B4: (All)
A6: Count of Modulo | B6: Modulo
A7: Estado de defecto | B7: AA | C7: AP | D7: BCM | E7: FM | F7: GL | G7: GR | H7: MM | I7: PAPM | J7: RE | K7: TR | L7: TX | M7: TRM | N7: AR | O7: Grand Total
A8: En tratamiento | B8: 2 | C8: 3 | D8: 4 | E8: 3 | F8: 1 | G8: 5 | H8: 2 | J8: 1 | K8: 3 | L8: 11 | M8: 4 | O8: 39
A9: Nuevo | B9: 3 | C9: 1 | F9: 1 | G9: 1 | H9: 1 | I9: 1 | K9: 1 | N9: 1 | O9: 10
A10: Grand Total | B10: 5 | C10: 4 | D10: 4 | E10: 3 | F10: 2 | G10: 6 | H10: 3 | I10: 1 | J10: 1 | K10: 4 | L10: 11 | M10: 4 | N10: 1 | O10: 49
A13: Pendientes cierre EPM
A15: Frente | B15: (All)
A17: Count of Modulo | B17: Modulo
A18: Estado de defecto | B18: BCM | C18: EW | D18: FI | E18: FM | F18: GL | G18: GR | H18: MM | I18: RE | J18: TR | K18: TX | L18: Grand Total
A19: Acción responsable test | C19: 1 | D19: 1 | E19: 2 | G19: 6 | I19: 1 | K19: 1 | L19: 12
A20: Propuesta de solución | B20: 1 | E20: 1 | F20: 1 | G20: 1 | H20: 1 | I20: 1 | J20: 1 | L20: 7
A21: Grand Total | B21: 1 | C21: 1 | D21: 1 | E21: 3 | F21: 1 | G21: 7 | H21: 1 | I21: 2 | J21: 1 | K21: 1 | L21: 19
A24: Pendientes IBM que frenan ciclo 2
A25: Bloqueante escenarios | B25: SI
A27: Count of Modulo | B27: Modulo
A28: Estado de defecto | B28: AA | C28: AP | D28: FM | E28: GL | F28: GR | G28: MM | H28: RE | I28: TX | J28: Grand Total
A29: En tratamiento | B29: 1 | C29: 2 | D29: 2 | E29: 1 | F29: 4 | G29: 2 | H29: 1 | I29: 10 | J29: 23
A30: Nuevo | C30: 1 | G30: 1 | J30: 2
A31: Grand Total | B31: 1 | C31: 3 | D31: 2 | E31: 1 | F31: 4 | G31: 3 | H31: 1 | I31: 10 | J31: 25

Sheet seguimiento_detalles_defecto
A1: N° | B1: Defecto | C1: Modulo | D1: ID Hallazgo Matriz | E1: Responsable del defecto | F1: Autor del defecto | G1: Antigüedad del defecto (promedio en días) | H1: Categoría de defecto | I1: Estado de defecto | J1: Fecha Propuesta de solución | K1: Comentarios | L1: Frente | M1: Bloqueante escenarios
A2: 1 | B2: H0-MM-Modif Pedido mensaje salida (8000001608) | C2: MM | D2: Nuevo | E2: =+VLOOKUP(B2,informacion_extra!A:F,2,FALSE) -> Wilmar Vargas Preciado (174) | F2: =+VLOOKUP(seguimiento_detalles_defecto!B2,informacion_extra!A:F,3,FALSE) -> MONICA PATRICIA GIRALDO PEREZ (192) | G2: =+VLOOKUP(B2,informacion_extra!A:F,4,FALSE) -> 4,54 | H2: =+VLOOKUP(B2,informacion_extra!A:F,5,FALSE) -> 0 | I2: =+VLOOKUP(B2,informacion_extra!A:F,6,FALSE) -> Nuevo | J2: 45755 | L2: NO FINANCIERO | M2: SI
A3: 2 | B3: H0_AP_Error en documento soporte (8000001605) | C3: AP | D3: Nuevo | E3: =+VLOOKUP(B3,informacion_extra!A:F,2,FALSE) -> Alberto Rivera Betancourt (822) | F3: =+VLOOKUP(seguimiento_detalles_defecto!B3,informacion_extra!A:F,3,FALSE) -> SINDY CRISTINA ALZATE ARIAS (201) | G3: =+VLOOKUP(B3,informacion_extra!A:F,4,FALSE) -> 4,65 | H3: =+VLOOKUP(B3,informacion_extra!A:F,5,FALSE) -> Desarrollo | I3: =+VLOOKUP(B3,informacion_extra!A:F,6,FALSE) -> Nuevo | L3: FINANCIERO | M3: SI
A4: 3 | B4: H0_TR_ERROR MONEDA E IMPORTE ME (8000001603) | C4: TR | D4: Nuevo | E4: =+VLOOKUP(B4,informacion_extra!A:F,2,FALSE) -> Nurky Castro (46) | F4: =+VLOOKUP(seguimiento_detalles_defecto!B4,informacion_extra!A:F,3,FALSE) -> ANGELA PATRICIA PERDOMO (175) | G4: =+VLOOKUP(B4,informacion_extra!A:F,4,FALSE) -> 5,65 | H4: =+VLOOKUP(B4,informacion_extra!A:F,5,FALSE) -> Desarrollo | I4: =+VLOOKUP(B4,informacion_extra!A:F,6,FALSE) -> En tratamiento | L4: FINANCIERO
A5: 4 | B5: H2_ RE_ EPM ERROR ANULACIÓN AJUSTE (8000001471) | C5: RE | D5: Nuevo | E5: =+VLOOKUP(B5,informacion_extra!A:F,2,FALSE) -> Pedro Emilio Jimenez Pabon (139) | F5: =+VLOOKUP(seguimiento_detalles_defecto!B5,informacion_extra!A:F,3,FALSE) -> NATALIA EUGENIA RAMIREZ MOLINA (193) | G5: =+VLOOKUP(B5,informacion_extra!A:F,4,FALSE) -> 13,91 | H5: =+VLOOKUP(B5,informacion_extra!A:F,5,FALSE) -> Desarrollo | I5: =+VLOOKUP(B5,informacion_extra!A:F,6,FALSE) -> En tratamiento | L5: FINANCIERO | M5: SI
A6: 5 | B6: H0_ RE_ CONTABILIDA FINANCIERA AGN (8000001462) | C6: RE | D6: Nuevo | E6: =+VLOOKUP(B6,informacion_extra!A:F,2,FALSE) -> NATALIA EUGENIA RAMIREZ MOLINA (193) | F6: =+VLOOKUP(seguimiento_detalles_defecto!B6,informacion_extra!A:F,3,FALSE) -> NATALIA EUGENIA RAMIREZ MOLINA (193) | G6: =+VLOOKUP(B6,informacion_extra!A:F,4,FALSE) -> 14,62 | H6: =+VLOOKUP(B6,informacion_extra!A:F,5,FALSE) -> Roles y perfiles | I6: =+VLOOKUP(B6,informacion_extra!A:F,6,FALSE) -> Acción responsable test | K6: 22/07/2025: Equipo tecnico esta revisando con el funcional la parametrizacion para dar fecha del ajuste 28/07/2025: Equipo tecnico regresa para funcional para su revisiòn. | L6: ET
A7: 6 | B7: H0_AA_Lentitud carga de datos en MC (8000001452) | C7: AA | D7: Nuevo | E7: =+VLOOKUP(B7,informacion_extra!A:F,2,FALSE) -> Natalia Manzaneda Palacios (258) | F7: =+VLOOKUP(seguimiento_detalles_defecto!B7,informacion_extra!A:F,3,FALSE) -> ANA MILENA IBARBO GUTIERREZ (320) | G7: =+VLOOKUP(B7,informacion_extra!A:F,4,FALSE) -> 14,73 | H7: =+VLOOKUP(B7,informacion_extra!A:F,5,FALSE) -> 0 | I7: =+VLOOKUP(B7,informacion_extra!A:F,6,FALSE) -> En tratamiento | L7: NO FINANCIERO
A8: 7 | B8: H0_MM_SC120 EROR VISTA WORZONE (8000001414) | C8: =+MID(B8,4,2) -> MM | D8: Nuevo | E8: =+VLOOKUP(B8,informacion_extra!A:F,2,FALSE) -> PAOLA ANDREA JIMENEZ RODRIGUEZ (492) | F8: =+VLOOKUP(seguimiento_detalles_defecto!B8,informacion_extra!A:F,3,FALSE) -> PAOLA ANDREA JIMENEZ RODRIGUEZ (492) | G8: =+VLOOKUP(B8,informacion_extra!A:F,4,FALSE) -> 18,96 | H8: =+VLOOKUP(B8,informacion_extra!A:F,5,FALSE) -> 0 | I8: =+VLOOKUP(B8,informacion_extra!A:F,6,FALSE) -> Propuesta de solución | L8: NO FINANCIERO
A9: 8 | B9: H0_AP_1236_ERROR ANULAR FRA MIRO (8000001412) | C9: =+MID(B9,4,2) -> AP | D9: =+MID(B9,7,4) -> 1236 | E9: =+VLOOKUP(B9,informacion_extra!A:F,2,FALSE) -> Wilmar Vargas Preciado (174) | F9: =+VLOOKUP(seguimiento_detalles_defecto!B9,informacion_extra!A:F,3,FALSE) -> SINDY CRISTINA ALZATE ARIAS (201) | G9: =+VLOOKUP(B9,informacion_extra!A:F,4,FALSE) -> 18,98 | H9: =+VLOOKUP(B9,informacion_extra!A:F,5,FALSE) -> Configuración | I9: =+VLOOKUP(B9,informacion_extra!A:F,6,FALSE) -> En tratamiento | J9: 29-07-2025 | L9: NO FINANCIERO | M9: SI
A10: 9 | B10: H0_EPM_TR_ErrorPagosDavivienda (8000001408) | C10: BCM | D10: 1408 | E10: =+VLOOKUP(B10,informacion_extra!A:F,2,FALSE) -> MANUEL HERNANDO SANTA JARA (132) | F10: =+VLOOKUP(seguimiento_detalles_defecto!B10,informacion_extra!A:F,3,FALSE) -> MANUEL HERNANDO SANTA JARA (132) | G10: =+VLOOKUP(B10,informacion_extra!A:F,4,FALSE) -> 19,60 | H10: =+VLOOKUP(B10,informacion_extra!A:F,5,FALSE) -> Desarrollo | I10: =+VLOOKUP(B10,informacion_extra!A:F,6,FALSE) -> Propuesta de solución | K10: Control de cambio | L10: FINANCIERO
A11: 10 | B11: H0_EWM_EWM_SC048_ERROR HU AUTOMATICA (8000001406) | C11: =+MID(B11,4,2) -> EW | D11: Nuevo | E11: =+VLOOKUP(B11,informacion_extra!A:F,2,FALSE) -> GUSTAVO ADOLFO GARCIA TRUJILLO (393) | F11: =+VLOOKUP(seguimiento_detalles_defecto!B11,informacion_extra!A:F,3,FALSE) -> GUSTAVO ADOLFO GARCIA TRUJILLO (393) | G11: =+VLOOKUP(B11,informacion_extra!A:F,4,FALSE) -> 19,61 | H11: =+VLOOKUP(B11,informacion_extra!A:F,5,FALSE) -> Funcionales | I11: =+VLOOKUP(B11,informacion_extra!A:F,6,FALSE) -> Acción responsable test | L11: NO FINANCIERO
A12: 11 | B12: H2_GR_1167_Validar extracción saldos FI- (8000001394) | C12: GR | D12: =+MID(B12,7,4) -> 1167 | E12: =+VLOOKUP(B12,informacion_extra!A:F,2,FALSE) -> Nicolas Sarmiento (218) | F12: =+VLOOKUP(seguimiento_detalles_defecto!B12,informacion_extra!A:F,3,FALSE) -> DAMARIS BIVIANA MURCIA SABOYA (103) | G12: =+VLOOKUP(B12,informacion_extra!A:F,4,FALSE) -> 19,70 | H12: =+VLOOKUP(B12,informacion_extra!A:F,5,FALSE) -> Configuración | I12: =+VLOOKUP(B12,informacion_extra!A:F,6,FALSE) -> Propuesta de solución | J12: Propuesta de solución | K12: 28/07/2025: Pendiente revisión prioridad EF extraccion de saldos SC180 y Porcentaje de participación | L12: FINANCIERO
A13: 12 | B13: H0_PAPM_1294_Capturadecontroladores (8000001391) | C13: =+MID(B13,4,4) -> PAPM | D13: 1294 | E13: =+VLOOKUP(B13,informacion_extra!A:F,2,FALSE) -> Raphael Gustavo Gimenes Trivaleti (219) | F13: =+VLOOKUP(seguimiento_detalles_defecto!B13,informacion_extra!A:F,3,FALSE) -> JUAN DAVID VARGAS RESTREPO (127) | G13: =+VLOOKUP(B13,informacion_extra!A:F,4,FALSE) -> 19,73 | H13: =+VLOOKUP(B13,informacion_extra!A:F,5,FALSE) -> 0 | I13: =+VLOOKUP(B13,informacion_extra!A:F,6,FALSE) -> Nuevo | K13: Abap:Danilo en tratamiento con Consultor Fiori, Entrega 28 de Julio para pruebas funcionales 7/29/2025: Equipo tecnico entrega para pruebas dia Lunes 28 | L13: TECNICO
A14: 13 | B14: H0_MM_1258_Carga registros info Proveed (8000001382) | C14: MM | D14: Nuevo | E14: =+VLOOKUP(B14,informacion_extra!A:F,2,FALSE) -> GUSTAVO ESPINOSA (646) | F14: =+VLOOKUP(seguimiento_detalles_defecto!B14,informacion_extra!A:F,3,FALSE) -> LUIS GERMAN PINEDA ARCILA (191) | G14: =+VLOOKUP(B14,informacion_extra!A:F,4,FALSE) -> 19,85 | H14: =+VLOOKUP(B14,informacion_extra!A:F,5,FALSE) -> Maestros | I14: =+VLOOKUP(B14,informacion_extra!A:F,6,FALSE) -> En tratamiento | K14: 28/07/2025: Se escala Nota - 884403/2025 CEDR: Despues de hacer varios simulacro se crea nota ya que el proceso se realiza con la herramienta de migracion de datos cockpik estandar de SAP | L14: NO FINANCIERO | M14: SI
A15: 14 | B15: H0_TR_BCM_ErrorPatronesCarga (8000001378) | C15: TR | D15: Nuevo | E15: =+VLOOKUP(B15,informacion_extra!A:F,2,FALSE) -> CAROLINA ECHEVERRI SANTA (783) | F15: =+VLOOKUP(seguimiento_detalles_defecto!B15,informacion_extra!A:F,3,FALSE) -> CAROLINA ECHEVERRI SANTA (783) | G15: =+VLOOKUP(B15,informacion_extra!A:F,4,FALSE) -> 19,86 | H15: =+VLOOKUP(B15,informacion_extra!A:F,5,FALSE) -> Configuración | I15: =+VLOOKUP(B15,informacion_extra!A:F,6,FALSE) -> Propuesta de solución | J15: 45854 | L15: FINANCIERO
A16: 15 | B16: H1_GL_1290_VALIDACION PPTAL NOMINA ERROR (8000001375) | C16: =+MID(B16,4,2) -> GL | D16: 724 | E16: =+VLOOKUP(B16,informacion_extra!A:F,2,FALSE) -> SANDRA JANET TAMAYO BEDOYA (199) | F16: =+VLOOKUP(seguimiento_detalles_defecto!B16,informacion_extra!A:F,3,FALSE) -> SANDRA JANET TAMAYO BEDOYA (199) | G16: =+VLOOKUP(B16,informacion_extra!A:F,4,FALSE) -> 19,96 | H16: =+VLOOKUP(B16,informacion_extra!A:F,5,FALSE) -> Desarrollo | I16: =+VLOOKUP(B16,informacion_extra!A:F,6,FALSE) -> Propuesta de solución | J16: 45847 | L16: FINANCIERO
A17: 16 | B17: H1_GL_1263_Error_recepcion_parcial (8000001373) | C17: =+MID(B17,4,2) -> GL | D17: =+MID(B17,7,4) -> 1263 | E17: =+VLOOKUP(B17,informacion_extra!A:F,2,FALSE) -> John Alejandro Rodriguez (41) | F17: =+VLOOKUP(seguimiento_detalles_defecto!B17,informacion_extra!A:F,3,FALSE) -> GLORIA ELENA AGUDELO ARENAS (181) | G17: =+VLOOKUP(B17,informacion_extra!A:F,4,FALSE) -> 19,98 | H17: =+VLOOKUP(B17,informacion_extra!A:F,5,FALSE) -> Desarrollo | I17: =+VLOOKUP(B17,informacion_extra!A:F,6,FALSE) -> En tratamiento | J17: 45870 | K17: 24/07/2025: Equipo tecnico ya entrego a pruebas funcionales | L17: FINANCIERO | M17: SI
A18: 17 | B18: H1_RE_ ERROR CONTABILIDA FINANCIERA PPTO (8000001368) | C18: =+MID(B18,4,2) -> RE | D18: Nuevo | E18: =+VLOOKUP(B18,informacion_extra!A:F,2,FALSE) -> NATALIA EUGENIA RAMIREZ MOLINA (193) | F18: =+VLOOKUP(seguimiento_detalles_defecto!B18,informacion_extra!A:F,3,FALSE) -> NATALIA EUGENIA RAMIREZ MOLINA (193) | G18: =+VLOOKUP(B18,informacion_extra!A:F,4,FALSE) -> 20,59 | H18: =+VLOOKUP(B18,informacion_extra!A:F,5,FALSE) -> Configuración | I18: =+VLOOKUP(B18,informacion_extra!A:F,6,FALSE) -> Propuesta de solución | K18: 18/07/2025: Se tansfierea Abap Raphael Gimenes, es una regla de IVA de FM que tiene problemas 22/07/2025: Equipo tecnico(Danilo) esta revisando con el funcional la parametrizacion para dar fecha del ajuste 28/07/2025: Equipo tecnico regresa para funcional para su revisiòn. | L18: ET
A19: 18 | B19: H0_FM_1303_Error en cumplimiento tarea (8000001361) | C19: =+MID(B19,4,2) -> FM | D19: =+MID(B19,7,4) -> 1303 | E19: =+VLOOKUP(B19,informacion_extra!A:F,2,FALSE) -> ANA MILENA CHADID JARAMILLO (697) | F19: =+VLOOKUP(seguimiento_detalles_defecto!B19,informacion_extra!A:F,3,FALSE) -> ANA MILENA CHADID JARAMILLO (697) | G19: =+VLOOKUP(B19,informacion_extra!A:F,4,FALSE) -> 20,62 | H19: =+VLOOKUP(B19,informacion_extra!A:F,5,FALSE) -> 0 | I19: =+VLOOKUP(B19,informacion_extra!A:F,6,FALSE) -> Propuesta de solución | J19: 45907 | L19: FINANCIERO
A20: 19 | B20: H0_FI_1308_Mensaje error no corresponde (8000001356) | C20: =+MID(B20,4,2) -> FI | D20: =+MID(B20,7,4) -> 1308 | E20: =+VLOOKUP(B20,informacion_extra!A:F,2,FALSE) -> ANA MILENA CHADID JARAMILLO (697) | F20: =+VLOOKUP(seguimiento_detalles_defecto!B20,informacion_extra!A:F,3,FALSE) -> ANA MILENA CHADID JARAMILLO (697) | G20: =+VLOOKUP(B20,informacion_extra!A:F,4,FALSE) -> 20,64 | H20: =+VLOOKUP(B20,informacion_extra!A:F,5,FALSE) -> Legados | I20: =+VLOOKUP(B20,informacion_extra!A:F,6,FALSE) -> Acción responsable test | L20: FINANCIERO
A21: 20 | B21: H0_MM_1141_ROLES Y PERFILES (8000001349) | C21: =+MID(B21,4,2) -> MM | D21: =+MID(B21,7,4) -> 1141 | E21: =+VLOOKUP(B21,informacion_extra!A:F,2,FALSE) -> GUSTAVO ESPINOSA (646) | F21: =+VLOOKUP(seguimiento_detalles_defecto!B21,informacion_extra!A:F,3,FALSE) -> PAOLA ANDREA JIMENEZ RODRIGUEZ (492) | G21: =+VLOOKUP(B21,informacion_extra!A:F,4,FALSE) -> 20,75 | H21: =+VLOOKUP(B21,informacion_extra!A:F,5,FALSE) -> 0 | I21: =+VLOOKUP(B21,informacion_extra!A:F,6,FALSE) -> En tratamiento | K21: 28/07/2025: Se escala Nota 885370/2025 CEDR: Nos encontramos buscando alternativas ya que el objeto de autorizacion no esta siendo efectivo en el rol | L21: NO FINANCIERO | M21: SI
A22: 21 | B22: H5_GR_1192_Eliminación reciproc x segmen (8000001342) | C22: GR | D22: =+MID(B22,7,4) -> 1192 | E22: =+VLOOKUP(B22,informacion_extra!A:F,2,FALSE) -> Nicolas Sarmiento (218) | F22: =+VLOOKUP(seguimiento_detalles_defecto!B22,informacion_extra!A:F,3,FALSE) -> DAMARIS BIVIANA MURCIA SABOYA (103) | G22: =+VLOOKUP(B22,informacion_extra!A:F,4,FALSE) -> 20,86 | H22: =+VLOOKUP(B22,informacion_extra!A:F,5,FALSE) -> Configuración | I22: =+VLOOKUP(B22,informacion_extra!A:F,6,FALSE) -> Acción responsable test | J22: Acción responsable test | K22: Devolución | L22: FINANCIERO
A23: 22 | B23: H5_GR_1193_Eliminación reciproc ubic.geo (8000001340) | C23: GR | D23: =+MID(B23,7,4) -> 1193 | E23: =+VLOOKUP(B23,informacion_extra!A:F,2,FALSE) -> Nicolas Sarmiento (218) | F23: =+VLOOKUP(seguimiento_detalles_defecto!B23,informacion_extra!A:F,3,FALSE) -> DAMARIS BIVIANA MURCIA SABOYA (103) | G23: =+VLOOKUP(B23,informacion_extra!A:F,4,FALSE) -> 20,87 | H23: =+VLOOKUP(B23,informacion_extra!A:F,5,FALSE) -> Configuración | I23: =+VLOOKUP(B23,informacion_extra!A:F,6,FALSE) -> Acción responsable test | J23: Acción responsable test | K23: Devolución | L23: FINANCIERO
A24: 23 | B24: H1_GR_interés minoritario (8000001331) | C24: GR | D24: Nuevo | E24: =+VLOOKUP(B24,informacion_extra!A:F,2,FALSE) -> Nicolas Sarmiento (218) | F24: =+VLOOKUP(seguimiento_detalles_defecto!B24,informacion_extra!A:F,3,FALSE) -> DAMARIS BIVIANA MURCIA SABOYA (103) | G24: =+VLOOKUP(B24,informacion_extra!A:F,4,FALSE) -> 20,89 | H24: =+VLOOKUP(B24,informacion_extra!A:F,5,FALSE) -> Configuración | I24: =+VLOOKUP(B24,informacion_extra!A:F,6,FALSE) -> Acción responsable test | J24: Acción responsable test | K24: Devolución | L24: FINANCIERO
A25: 24 | B25: H1_GR_interés no contr utilidades ejerci (8000001328) | C25: GR | D25: Nuevo | E25: =+VLOOKUP(B25,informacion_extra!A:F,2,FALSE) -> Nicolas Sarmiento (218) | F25: =+VLOOKUP(seguimiento_detalles_defecto!B25,informacion_extra!A:F,3,FALSE) -> DAMARIS BIVIANA MURCIA SABOYA (103) | G25: =+VLOOKUP(B25,informacion_extra!A:F,4,FALSE) -> 20,89 | H25: =+VLOOKUP(B25,informacion_extra!A:F,5,FALSE) -> Configuración | I25: =+VLOOKUP(B25,informacion_extra!A:F,6,FALSE) -> En tratamiento | J25: 45849 | K25: Devolución | L25: FINANCIERO | M25: SI
A26: 25 | B26: H1_GR_Eliminacion de dividendos (8000001326) | C26: GR | D26: Nuevo | E26: =+VLOOKUP(B26,informacion_extra!A:F,2,FALSE) -> Nicolas Sarmiento (218) | F26: =+VLOOKUP(seguimiento_detalles_defecto!B26,informacion_extra!A:F,3,FALSE) -> DAMARIS BIVIANA MURCIA SABOYA (103) | G26: =+VLOOKUP(B26,informacion_extra!A:F,4,FALSE) -> 20,90 | H26: =+VLOOKUP(B26,informacion_extra!A:F,5,FALSE) -> Configuración | I26: =+VLOOKUP(B26,informacion_extra!A:F,6,FALSE) -> Acción responsable test | J26: Acción responsable test | K26: Devolución | L26: FINANCIERO
A27: 26 | B27: H5_GR_325_acciones poseídas y % particip (8000001322) | C27: GR | D27: 325 | E27: =+VLOOKUP(B27,informacion_extra!A:F,2,FALSE) -> Nicolas Sarmiento (218) | F27: =+VLOOKUP(seguimiento_detalles_defecto!B27,informacion_extra!A:F,3,FALSE) -> DAMARIS BIVIANA MURCIA SABOYA (103) | G27: =+VLOOKUP(B27,informacion_extra!A:F,4,FALSE) -> 20,94 | H27: =+VLOOKUP(B27,informacion_extra!A:F,5,FALSE) -> Configuración | I27: =+VLOOKUP(B27,informacion_extra!A:F,6,FALSE) -> En tratamiento | K27: 25/07/2025: Devolución 16/07/2025: EPM esta validandado EF y darnos sus comentarios para iicar con las firmas 11/07/2025: Este es el del desarrollo, ABAP Documento de EF aprobado para desarrollo | L27: FINANCIERO
A28: 27 | B28: H1_AP_1198_Errores inf Portal Proveedore (8000001321) | C28: =+MID(B28,4,2) -> AP | D28: =+MID(B28,7,4) -> 1198 | E28: =+VLOOKUP(B28,informacion_extra!A:F,2,FALSE) -> Alberto Rivera Betancourt (822) | F28: =+VLOOKUP(seguimiento_detalles_defecto!B28,informacion_extra!A:F,3,FALSE) -> PAULA ANDREA MERCADO FLOREZ (776) | G28: =+VLOOKUP(B28,informacion_extra!A:F,4,FALSE) -> 20,95 | H28: =+VLOOKUP(B28,informacion_extra!A:F,5,FALSE) -> Desarrollo | I28: =+VLOOKUP(B28,informacion_extra!A:F,6,FALSE) -> En tratamiento | J28: 45853 | L28: FINANCIERO | M28: SI
A29: 28 | B29: H4_GR_674_Generar EEFF separados (8000001319) | C29: GR | D29: 674 | E29: =+VLOOKUP(B29,informacion_extra!A:F,2,FALSE) -> Gustavo Marques Cussioli (244) | F29: =+VLOOKUP(seguimiento_detalles_defecto!B29,informacion_extra!A:F,3,FALSE) -> DAMARIS BIVIANA MURCIA SABOYA (103) | G29: =+VLOOKUP(B29,informacion_extra!A:F,4,FALSE) -> 20,95 | H29: =+VLOOKUP(B29,informacion_extra!A:F,5,FALSE) -> Configuración | I29: =+VLOOKUP(B29,informacion_extra!A:F,6,FALSE) -> En tratamiento | J29: Por Confirmar | K29: Se requiere para la salida en producción | L29: FINANCIERO | M29: SI
A30: 29 | B30: H2_GR_1090_GAAP Utilidades no realizadas (8000001317) | C30: GR | D30: =+MID(B30,7,4) -> 1090 | E30: =+VLOOKUP(B30,informacion_extra!A:F,2,FALSE) -> Nicolas Sarmiento (218) | F30: =+VLOOKUP(seguimiento_detalles_defecto!B30,informacion_extra!A:F,3,FALSE) -> DAMARIS BIVIANA MURCIA SABOYA (103) | G30: =+VLOOKUP(B30,informacion_extra!A:F,4,FALSE) -> 20,96 | H30: =+VLOOKUP(B30,informacion_extra!A:F,5,FALSE) -> Configuración | I30: =+VLOOKUP(B30,informacion_extra!A:F,6,FALSE) -> En tratamiento | K30: no tiene solución en SAP. Ya Mile y Pedro saben esto pero estamos esperando que se resuelva el hallazgo del escenario de arrendamiento financiero que está de lado de Carlos Martins para hacer una reunión e informarle a EPM. Porque estos dos escenarios están dentro del mismo GAP 11/07/2025: Mile y Pedro lo validan | L30: FINANCIERO | M30: SI
A31: 30 | B31: H2_GR_1094_Eliminación Inversión y patri (8000001309) | C31: GR | D31: =+MID(B31,7,4) -> 1094 | E31: =+VLOOKUP(B31,informacion_extra!A:F,2,FALSE) -> Nicolas Sarmiento (218) | F31: =+VLOOKUP(seguimiento_detalles_defecto!B31,informacion_extra!A:F,3,FALSE) -> DAMARIS BIVIANA MURCIA SABOYA (103) | G31: =+VLOOKUP(B31,informacion_extra!A:F,4,FALSE) -> 20,97 | H31: =+VLOOKUP(B31,informacion_extra!A:F,5,FALSE) -> Configuración | I31: =+VLOOKUP(B31,informacion_extra!A:F,6,FALSE) -> Acción responsable test | J31: Acción responsable test | K31: Devolución | L31: FINANCIERO
A32: 31 | B32: H2_GR_1101_GAAP Arrendamiento Fro arrend (8000001304) | C32: GR | D32: =+MID(B32,7,4) -> 1101 | E32: =+VLOOKUP(B32,informacion_extra!A:F,2,FALSE) -> Carlos Martins de Lima (778) | F32: =+VLOOKUP(seguimiento_detalles_defecto!B32,informacion_extra!A:F,3,FALSE) -> DAMARIS BIVIANA MURCIA SABOYA (103) | G32: =+VLOOKUP(B32,informacion_extra!A:F,4,FALSE) -> 20,99 | H32: =+VLOOKUP(B32,informacion_extra!A:F,5,FALSE) -> Configuración | I32: =+VLOOKUP(B32,informacion_extra!A:F,6,FALSE) -> En tratamiento | K32: No es hallazgo indican que es por GR, Data Collection pero no, no es la herramienta para eliminaciones. Sin embargo, existe un hallazgo (el que tiene Carlos) que sí trata las eliminaciones. | L32: FINANCIERO | M32: SI
A33: 32 | B33: H1_GR_1300_Conversion Moneda 126000 (8000001300) | C33: GR | D33: =+MID(B33,7,4) -> 1300 | E33: =+VLOOKUP(B33,informacion_extra!A:F,2,FALSE) -> Nicolas Sarmiento (218) | F33: =+VLOOKUP(seguimiento_detalles_defecto!B33,informacion_extra!A:F,3,FALSE) -> DAMARIS BIVIANA MURCIA SABOYA (103) | G33: =+VLOOKUP(B33,informacion_extra!A:F,4,FALSE) -> 21,00 | H33: =+VLOOKUP(B33,informacion_extra!A:F,5,FALSE) -> Configuración | I33: =+VLOOKUP(B33,informacion_extra!A:F,6,FALSE) -> Acción responsable test | J33: Acción responsable test | L33: FINANCIERO
A34: 33 | B34: H1_FM_758 Controller (8000001296) | C34: =+MID(B34,4,2) -> FM | D34: =+MID(B34,7,4) -> 758 | E34: =+VLOOKUP(B34,informacion_extra!A:F,2,FALSE) -> Jenny Carolina Suarez (101) | F34: =+VLOOKUP(seguimiento_detalles_defecto!B34,informacion_extra!A:F,3,FALSE) -> MISAEL ENRIQUE ARAUJO DIAZ (701) | G34: =+VLOOKUP(B34,informacion_extra!A:F,4,FALSE) -> 21,49 | H34: =+VLOOKUP(B34,informacion_extra!A:F,5,FALSE) -> Desarrollo | I34: =+VLOOKUP(B34,informacion_extra!A:F,6,FALSE) -> En tratamiento | K34: 11/07/2025: Pendiente por fecha equipo tecnico | L34: FINANCIERO | M34: SI
A35: 34 | B35: H3_AA_668_ Liberación de reserva fiscal (8000001281) | C35: =+MID(B35,4,2) -> AA | D35: 668 | E35: =+VLOOKUP(B35,informacion_extra!A:F,2,FALSE) -> Oscar Mauricio Parada (49) | F35: =+VLOOKUP(seguimiento_detalles_defecto!B35,informacion_extra!A:F,3,FALSE) -> LEIDY FABIOLA CARDENAS SUAREZ (188) | G35: =+VLOOKUP(B35,informacion_extra!A:F,4,FALSE) -> 21,62 | H35: =+VLOOKUP(B35,informacion_extra!A:F,5,FALSE) -> Desarrollo | I35: =+VLOOKUP(B35,informacion_extra!A:F,6,FALSE) -> En tratamiento | J35: 45867 | L35: FINANCIERO | M35: SI
A36: 35 | B36: H0_TX_1248_Errorcargamanualformato1001 (8000001272) | C36: =+MID(B36,4,2) -> TX | D36: =+MID(B36,7,4) -> 1248 | E36: =+VLOOKUP(B36,informacion_extra!A:F,2,FALSE) -> Raphael Gustavo Gimenes Trivaleti (219) | F36: =+VLOOKUP(seguimiento_detalles_defecto!B36,informacion_extra!A:F,3,FALSE) -> ELIZABETH MARIA HERNANDEZ RUEDA (767) | G36: =+VLOOKUP(B36,informacion_extra!A:F,4,FALSE) -> 21,63 | H36: =+VLOOKUP(B36,informacion_extra!A:F,5,FALSE) -> Desarrollo | I36: =+VLOOKUP(B36,informacion_extra!A:F,6,FALSE) -> En tratamiento | J36: 45877 | K36: 14/07/2025: No es CC, se realizaran pruebas con usuarios. Revisión equipo Abap-Raphael Gimenes | L36: FINANCIERO | M36: SI
A37: 36 | B37: H0_FM_1231_Ejec Gast GT (8000001260) | C37: =+MID(B37,4,2) -> FM | D37: =+MID(B37,7,4) -> 1231 | E37: =+VLOOKUP(B37,informacion_extra!A:F,2,FALSE) -> Lina María Rodríguez Bailón (171) | F37: =+VLOOKUP(seguimiento_detalles_defecto!B37,informacion_extra!A:F,3,FALSE) -> MISAEL ENRIQUE ARAUJO DIAZ (701) | G37: =+VLOOKUP(B37,informacion_extra!A:F,4,FALSE) -> 21,74 | H37: =+VLOOKUP(B37,informacion_extra!A:F,5,FALSE) -> Desarrollo | I37: =+VLOOKUP(B37,informacion_extra!A:F,6,FALSE) -> En tratamiento | J37: Por confirmar | K37: 11/07/2025: Exigir Matriz 14/07/2025: El equipo tecnico entrega el 16 de julio 18/07/2025: El equipo tecnico entrego el 17 de julio, en pruebas de Lina | L37: FINANCIERO | M37: SI
A38: 37 | B38: H8_TX_630_F5252 Configuración_generación (8000001247) | C38: =+MID(B38,4,2) -> TX | D38: =+MID(B38,7,4) -> 630_ | E38: =+VLOOKUP(B38,informacion_extra!A:F,2,FALSE) -> Ana Maria Brito Llerena (151) | F38: =+VLOOKUP(seguimiento_detalles_defecto!B38,informacion_extra!A:F,3,FALSE) -> LINA MARIA SANCHEZ ESCOBAR (771) | G38: =+VLOOKUP(B38,informacion_extra!A:F,4,FALSE) -> 22,83 | H38: =+VLOOKUP(B38,informacion_extra!A:F,5,FALSE) -> Desarrollo | I38: =+VLOOKUP(B38,informacion_extra!A:F,6,FALSE) -> En tratamiento | J38: Escalado a SAP 775798/2025 | K38: 28/07/2025: Se escalo a SAP en espera de respuesta Caso 775798/2025 Revisión eqipo Abap | L38: FINANCIERO | M38: SI
A39: 38 | B39: H0_TX_Comparativo por cuentas ICA (8000001596) | C39: TX | D39: Nuevo | E39: =+VLOOKUP(B39,informacion_extra!A:F,2,FALSE) -> Diana Carolina Sanchez Aguirre (165) | F39: =+VLOOKUP(seguimiento_detalles_defecto!B39,informacion_extra!A:F,3,FALSE) -> LEIDY FABIOLA CARDENAS SUAREZ (188) | G39: =+VLOOKUP(B39,informacion_extra!A:F,4,FALSE) -> 5,87 | H39: =+VLOOKUP(B39,informacion_extra!A:F,5,FALSE) -> 0 | I39: Propuesta de solución | K39: 23/07/2025: Nuevo, a la espera de asignación ABAP. 28/07/2025: Equipo tecnico regresa para funcional para su pruebas . | L39: TECNICO | M39: SI
A40: 39 | B40: H0_TX_Comparativo por impuestos ICA (8000001594) | C40: TX | D40: Nuevo | E40: =+VLOOKUP(B40,informacion_extra!A:F,2,FALSE) -> Diana Carolina Sanchez Aguirre (165) | F40: =+VLOOKUP(seguimiento_detalles_defecto!B40,informacion_extra!A:F,3,FALSE) -> LEIDY FABIOLA CARDENAS SUAREZ (188) | G40: =+VLOOKUP(B40,informacion_extra!A:F,4,FALSE) -> 5,87 | H40: =+VLOOKUP(B40,informacion_extra!A:F,5,FALSE) -> 0 | I40: Propuesta de solución | K40: 23/07/2025: Nuevo, a la espera de asignación ABAP. 28/07/2025: Equipo tecnico regresa para funcional para su pruebas . | L40: TECNICO | M40: SI
...

Sheet resumen_diario_estado_defectos
A1: Fecha | B1: Nuevo | C1: Tratamiento | D1: Transferido | E1: Acción responsable | F1: Propuesta de solución | G1: Confirmados
A2: 14/07/2025 | B2: 7 | C2: 32 | D2: 2 | E2: 11 | F2: 15 | G2: 5
A3: 15/07/2025 | B3: 9 | C3: 34 | D3: 0 | E3: 12 | F3: 12 | G3: 7
A4: 16/07/2025 | B4: 7 | C4: 35 | D4: 0 | E4: 12 | F4: 13 | G4: 7
A5: 18/07/2025 | B5: 7 | C5: 28 | D5: 0 | E5: 17 | F5: 20 | G5: 10
A6: 21/07/2025 | B6: 8 | C6: 28 | D6: 0 | E6: 18 | F6: 21 | G6: 17
A7: 22/07/2025 | B7: 10 | C7: 37 | D7: 0 | E7: 16 | F7: 19 | G7: 23
A8: 28/07/2025 | B8: 12 | C8: 46 | D8: 0 | E8: 8 | F8: 9 | G8: 41
